<?xml version="1.0"?>
<robot name="hands_one">

  <!-- Connect base_link to the world so it stays fixed in space -->
  <link name="world"/>

  <joint name="world_fixed" type="fixed">
    <parent link="world"/>
    <child link="base_link"/>
    <origin xyz="0 0 0.5" rpy="1.5708 0 0"/>
  </joint>

  <link name="base_link"/>

  <gazebo reference="base_link">
    <static>true</static>
  </gazebo>

  <joint name="base_fixed" type="fixed">
    <parent link="base_link"/>
    <child link="PalmMid_link"/>
  </joint>

  <!-- Palm Mid link -->
  <link name="PalmMid_link">
    <visual>
      <geometry>
        <mesh filename="package://hands_one/meshes/PalmMidUpdated.stl" scale="0.001 0.001 0.001"/>
      </geometry>
      <material name="gray">
        <color rgba="0.5 0.5 0.5 1"/>
      </material>
    </visual>

    <collision>
      <geometry>
        <mesh filename="package://hands_one/meshes/PalmMidUpdated.stl" scale="0.001 0.001 0.001"/>
      </geometry>
    </collision>

    <inertial>
      <mass value="0.5"/>
      <origin xyz="0 0 0" rpy="0 0 0"/>
      <inertia ixx="0.001" ixy="0" ixz="0" iyy="0.001" iyz="0" izz="0.001"/>
    </inertial>
  </link>

  <gazebo reference="PalmMid_link"> 
    <material>Gazebo/Gray</material> 
    <gravity>false</gravity> 
  </gazebo>

  <!-- Palm Back link -->
  <link name="PalmBackCover_link">
    <visual>
      <geometry>
        <mesh filename="package://hands_one/meshes/PalmBackCoverUpdated.stl" scale="0.001 0.001 0.001"/>
      </geometry>
      <material name="red">
        <color rgba="1 0 0 1"/>
      </material>
    </visual>
    <collision>
      <geometry>
        <mesh filename="package://hands_one/meshes/PalmBackCoverUpdated.stl" scale="0.001 0.001 0.001"/>
      </geometry>
    </collision>
    <inertial>
      <mass value="0.1"/>
      <origin xyz="0 0 0" rpy="0 0 0"/>
      <inertia ixx="0.0001" ixy="0" ixz="0" iyy="0.0001" iyz="0" izz="0.0001"/>
    </inertial>
  </link>

  <!-- Palm Front link -->
  <link name="PalmFrontCover_link">
    <visual>
      <geometry>
        <mesh filename="package://hands_one/meshes/PalmFrontCover.stl" scale="0.001 0.001 0.001"/>
      </geometry>
      <material name="white">
        <color rgba="1 1 1 1"/>
      </material>
    </visual>
    <collision>
      <geometry>
        <mesh filename="package://hands_one/meshes/PalmFrontCover.stl" scale="0.001 0.001 0.001"/>
      </geometry>
    </collision>
    <inertial>
      <mass value="0.1"/>
      <origin xyz="0 0 0" rpy="0 0 0"/>
      <inertia ixx="0.0001" ixy="0" ixz="0" iyy="0.0001" iyz="0" izz="0.0001"/>
    </inertial>
  </link>

  <!-- Joint connecting PalmBackCover to PalmMid -->
  <joint name="PalmBack_joint" type="fixed">
    <parent link="PalmMid_link"/>
    <child link="PalmBackCover_link"/>
    <origin xyz="0 -0.0050 -0.0075" rpy="0 0 0"/>
  </joint>

  <!-- Joint connecting PalmFrontCover to PalmMid -->
  <joint name="PalmFront_joint" type="fixed">
    <parent link="PalmMid_link"/>
    <child link="PalmFrontCover_link"/>
    <origin xyz="0 -0.0050 0.0175" rpy="0 0 0"/>
  </joint>

  <!-- Little Finger Servo -->
  <link name="LittleServo_link">
    <visual>
      <geometry>
        <mesh filename="package://hands_one/meshes/servo.stl" scale="0.001 0.001 0.001"/>
      </geometry>
      <material name="black">
        <color rgba="0 0 0 1"/>
      </material>
    </visual>
    <collision>
      <geometry>
        <mesh filename="package://hands_one/meshes/servo.stl" scale="0.001 0.001 0.001"/>
      </geometry>
    </collision>
    <inertial>
      <mass value="0.1"/>
      <origin xyz="0 0 0" rpy="0 0 0"/>
      <inertia ixx="0.0001" ixy="0" ixz="0" iyy="0.0001" iyz="0" izz="0.0001"/>
    </inertial>
  </link>

  <!-- Ring Finger Servo -->
  <link name="RingServo_link">
    <visual>
      <geometry>
        <mesh filename="package://hands_one/meshes/servo.stl" scale="0.001 0.001 0.001"/>
      </geometry>
      <material name="black">
        <color rgba="0 0 0 1"/>
      </material>
    </visual>
    <collision>
      <geometry>
        <mesh filename="package://hands_one/meshes/servo.stl" scale="0.001 0.001 0.001"/>
      </geometry>
    </collision>
    <inertial>
      <mass value="0.1"/>
      <origin xyz="0 0 0" rpy="0 0 0"/>
      <inertia ixx="0.0001" ixy="0" ixz="0" iyy="0.0001" iyz="0" izz="0.0001"/>
    </inertial>
  </link>

  <!-- Middle Finger Servo -->
  <link name="MiddleServo_link">
    <visual>
      <geometry>
        <mesh filename="package://hands_one/meshes/servo.stl" scale="0.001 0.001 0.001"/>
      </geometry>
      <material name="black">
        <color rgba="0 0 0 1"/>
      </material>
    </visual>
    <collision>
      <geometry>
        <mesh filename="package://hands_one/meshes/servo.stl" scale="0.001 0.001 0.001"/>
      </geometry>
    </collision>
    <inertial>
      <mass value="0.1"/>
      <origin xyz="0 0 0" rpy="0 0 0"/>
      <inertia ixx="0.0001" ixy="0" ixz="0" iyy="0.0001" iyz="0" izz="0.0001"/>
    </inertial>
  </link>

  <!-- Index Finger Servo -->
  <link name="IndexServo_link">
    <visual>
      <geometry>
        <mesh filename="package://hands_one/meshes/servo.stl" scale="0.001 0.001 0.001"/>
      </geometry>
      <material name="black">
        <color rgba="0 0 0 1"/>
      </material>
    </visual>
    <collision>
      <geometry>
        <mesh filename="package://hands_one/meshes/servo.stl" scale="0.001 0.001 0.001"/>
      </geometry>
    </collision>
    <inertial>
      <mass value="0.1"/>
      <origin xyz="0 0 0" rpy="0 0 0"/>
      <inertia ixx="0.0001" ixy="0" ixz="0" iyy="0.0001" iyz="0" izz="0.0001"/>
    </inertial>
  </link>

  <!-- Thumb Servo -->
  <link name="ThumbServo_link">
    <visual>
      <geometry>
        <mesh filename="package://hands_one/meshes/servo.stl" scale="0.001 0.001 0.001"/>
      </geometry>
      <material name="black">
        <color rgba="0 0 0 1"/>
      </material>
    </visual>
    <collision>
      <geometry>
        <mesh filename="package://hands_one/meshes/servo.stl" scale="0.001 0.001 0.001"/>
      </geometry>
    </collision>
    <inertial>
      <mass value="0.1"/>
      <origin xyz="0 0 0" rpy="0 0 0"/>
      <inertia ixx="0.0001" ixy="0" ixz="0" iyy="0.0001" iyz="0" izz="0.0001"/>
    </inertial>
  </link>

  <!-- Joint connecting LittleFingerServo to PalmMid -->
  <joint name="LittleServo_joint" type="fixed">
    <parent link="PalmMid_link"/>
    <child link="LittleServo_link"/>
    <origin xyz="-0.0375 0.00875 -0.0020" rpy="1.5708 0 1.5708"/>
    <dynamics damping="0.5" friction="0.2"/>
  </joint>

  <!-- Joint connecting RingFingerServo to PalmMid -->
  <joint name="RingServo_joint" type="fixed">
    <parent link="PalmMid_link"/>
    <child link="RingServo_link"/>
    <origin xyz="-0.0125 0.02125 -0.0020" rpy="1.5708 0 1.5708"/>
    <dynamics damping="0.5" friction="0.2"/>
  </joint>

  <!-- Joint connecting MiddleFingerServo to PalmMid -->
  <joint name="MiddleServo_joint" type="fixed">
    <parent link="PalmMid_link"/>
    <child link="MiddleServo_link"/>
    <origin xyz="0.0125 0.02875 -0.0020" rpy="1.5708 0 1.5708"/>
    <dynamics damping="0.5" friction="0.2"/>
  </joint>

  <!-- Joint connecting IndexFingerServo to PalmMid -->
  <joint name="IndexServo_joint" type="fixed">
    <parent link="PalmMid_link"/>
    <child link="IndexServo_link"/>
    <origin xyz="0.0375 0.02125 -0.0020" rpy="1.5708 0 1.5708"/>
    <dynamics damping="0.5" friction="0.2"/>
  </joint>

  <!-- Joint connecting ThumbFingerServo to PalmMid -->
  <joint name="ThumbServo_joint" type="fixed">
    <parent link="PalmMid_link"/>
    <child link="ThumbServo_link"/>
    <origin xyz="0.01924 -0.03931 0.01795" rpy="1.5708 0 0.7854"/>
    <dynamics damping="0.5" friction="0.2"/>
  </joint>

  <!-- Little Abduction Mechanism -->
  <link name="LittleMechanism_link">
    <visual>
      <origin xyz="0 0.0157 0" rpy="0 0 0"/>
      <geometry>
        <mesh filename="package://hands_one/meshes/AbductionMechanism.stl" scale="0.001 0.001 0.001"/>
      </geometry>
      <material name="red">
        <color rgba="1 0 0 1"/>
      </material>
    </visual>
    <collision>
      <origin xyz="0 0.0157 0" rpy="0 0 0"/>
      <geometry>
        <mesh filename="package://hands_one/meshes/AbductionMechanism.stl" scale="0.001 0.001 0.001"/>
      </geometry>
    </collision>
    <inertial>
      <mass value="0.1"/>
      <origin xyz="0 0 0" rpy="0 0 0"/>
      <inertia ixx="0.0001" ixy="0" ixz="0" iyy="0.0001" iyz="0" izz="0.0001"/>
    </inertial>
  </link>

  <!-- Joint connecting Little Abduction Mechanism to LittleFingerServo -->
  <joint name="LittleMechanism_joint" type="revolute">
    <parent link="LittleServo_link"/>
    <child link="LittleMechanism_link"/>
    <origin xyz="0.0054 0.0175 0" rpy="-1.5708 -1.5708 0"/>
    <axis xyz="0 0 1"/>
    <limit lower="-0.1" upper="0.52" effort="1" velocity="1"/>
    <dynamics damping="0.5" friction="0.2"/>
  </joint>

  <!-- Ring Abduction Mechanism -->
  <link name="RingMechanism_link">
    <visual>
      <origin xyz="0 0.0157 0" rpy="0 0 0"/>
      <geometry>
        <mesh filename="package://hands_one/meshes/AbductionMechanism.stl" scale="0.001 0.001 0.001"/>
      </geometry>
      <material name="red">
        <color rgba="1 0 0 1"/>
      </material>
    </visual>
    <collision>
      <origin xyz="0 0.0157 0" rpy="0 0 0"/>
      <geometry>
        <mesh filename="package://hands_one/meshes/AbductionMechanism.stl" scale="0.001 0.001 0.001"/>
      </geometry>
    </collision>
    <inertial>
      <mass value="0.1"/>
      <origin xyz="0 0 0" rpy="0 0 0"/>
      <inertia ixx="0.0001" ixy="0" ixz="0" iyy="0.0001" iyz="0" izz="0.0001"/>
    </inertial>
  </link>

  <!-- Joint connecting Ring Abduction Mechanism to RingFingerServo -->
  <joint name="RingMechanism_joint" type="revolute">
    <parent link="RingServo_link"/>
    <child link="RingMechanism_link"/>
    <origin xyz="0.0054 0.0175 0" rpy="-1.5708 -1.5708 0"/>
    <axis xyz="0 0 1"/>
    <limit lower="-0.1" upper="0.35" effort="1" velocity="1"/>
    <dynamics damping="0.5" friction="0.2"/>
  </joint>

  <!-- Middle Abduction Mechanism -->
  <link name="MiddleMechanism_link">
    <visual>
      <origin xyz="0 0.0157 0" rpy="0 0 0"/>
      <geometry>
        <mesh filename="package://hands_one/meshes/AbductionMechanism.stl" scale="0.001 0.001 0.001"/>
      </geometry>
      <material name="red">
        <color rgba="1 0 0 1"/>
      </material>
    </visual>
    <collision>
      <origin xyz="0 0.0157 0" rpy="0 0 0"/>
      <geometry>
        <mesh filename="package://hands_one/meshes/AbductionMechanism.stl" scale="0.001 0.001 0.001"/>
      </geometry>
    </collision>
    <inertial>
      <mass value="0.1"/>
      <origin xyz="0 0 0" rpy="0 0 0"/>
      <inertia ixx="0.0001" ixy="0" ixz="0" iyy="0.0001" iyz="0" izz="0.0001"/>
    </inertial>
  </link>

  <!-- Joint connecting Middle Abduction Mechanism to IndexFingerServo -->
  <joint name="MiddleMechanism_joint" type="revolute">
    <parent link="MiddleServo_link"/>
    <child link="MiddleMechanism_link"/>
    <origin xyz="0.0054 0.0175 0" rpy="-1.5708 -1.5708 0"/>
    <axis xyz="0 0 1"/>
    <limit lower="-0.2" upper="0.2" effort="1" velocity="1"/>
    <dynamics damping="0.5" friction="0.2"/>
  </joint>

  <!-- Index Abduction Mechanism -->
  <link name="IndexMechanism_link">
    <visual>
      <origin xyz="0 0.0157 0" rpy="0 0 0"/>
      <geometry>
        <mesh filename="package://hands_one/meshes/AbductionMechanism.stl" scale="0.001 0.001 0.001"/>
      </geometry>
      <material name="red">
        <color rgba="1 0 0 1"/>
      </material>
    </visual>
    <collision>
      <origin xyz="0 0.0157 0" rpy="0 0 0"/>
      <geometry>
        <mesh filename="package://hands_one/meshes/AbductionMechanism.stl" scale="0.001 0.001 0.001"/>
      </geometry>
    </collision>
    <inertial>
      <mass value="0.1"/>
      <origin xyz="0 0 0" rpy="0 0 0"/>
      <inertia ixx="0.0001" ixy="0" ixz="0" iyy="0.0001" iyz="0" izz="0.0001"/>
    </inertial>
  </link>

  <!-- Joint connecting Index Abduction Mechanism to IndexFingerServo -->
  <joint name="IndexMechanism_joint" type="revolute">
    <parent link="IndexServo_link"/>
    <child link="IndexMechanism_link"/>
    <origin xyz="0.0054 0.0175 0" rpy="-1.5708 -1.5708 0"/>
    <axis xyz="0 0 1"/>
    <limit lower="-0.52" upper="0.1" effort="1" velocity="1"/>
    <dynamics damping="0.5" friction="0.2"/>
  </joint>

  <!-- Thumb Abduction Mechanism -->
  <link name="ThumbMechanism_link">
    <visual>
      <origin xyz="0 0.0157 0" rpy="0 0 0"/>
      <geometry>
        <mesh filename="package://hands_one/meshes/AbductionMechanism.stl" scale="0.001 0.001 0.001"/>
      </geometry>
      <material name="red">
        <color rgba="1 0 0 1"/>
      </material>
    </visual>
    <collision>
      <origin xyz="0 0.0157 0" rpy="0 0 0"/>
      <geometry>
        <mesh filename="package://hands_one/meshes/AbductionMechanism.stl" scale="0.001 0.001 0.001"/>
      </geometry>
    </collision>
    <inertial>
      <mass value="0.1"/>
      <origin xyz="0 0 0" rpy="0 0 0"/>
      <inertia ixx="0.0001" ixy="0" ixz="0" iyy="0.0001" iyz="0" izz="0.0001"/>
    </inertial>
  </link>

  <!-- Joint connecting Thumb Abduction Mechanism to ThumbFingerServo -->
  <joint name="ThumbMechanism_joint" type="revolute">
    <parent link="ThumbServo_link"/>
    <child link="ThumbMechanism_link"/>
    <origin xyz="0.0054 0.0175 0" rpy="-1.5708 -1.5708 0"/>
    <axis xyz="0 0 1"/>
    <limit lower="-0.6" upper="1.1" effort="1" velocity="1"/>
    <dynamics damping="0.5" friction="0.2"/>
  </joint>

  <!-- LittleProximal Gearbox -->
  <link name="Little_ProximalGearbox_link">
    <visual>
      <origin xyz="0 -0.003 0" rpy="0 0 0"/>
      <geometry>
        <mesh filename="package://hands_one/meshes/Gearbox1.stl" scale="0.001 0.001 0.001"/>
      </geometry>
      <material name="green">
        <color rgba="0 1 0 1"/>
      </material>
    </visual>
    <collision>
      <origin xyz="0 -0.003 0" rpy="0 0 0"/>
      <geometry>
        <mesh filename="package://hands_one/meshes/Gearbox1.stl" scale="0.001 0.001 0.001"/>
      </geometry>
    </collision>
    <inertial>
      <mass value="0.1"/>
      <origin xyz="0 0 0" rpy="0 0 0"/>
      <inertia ixx="0.0001" ixy="0" ixz="0" iyy="0.0001" iyz="0" izz="0.0001"/>
    </inertial>
  </link>

  <!-- Joint connecting Little Finger Gearbox to Little Finger Mechanism -->
  <joint name="Little_ProximalGearbox_joint" type="revolute">
    <parent link="LittleMechanism_link"/>
    <child link="Little_ProximalGearbox_link"/>
    <origin xyz="0 0.02375 -0.003" rpy="0 -1.57 -3.14159"/>
    <axis xyz="0 0 1"/>
    <limit lower="-0.3" upper="1.57" effort="1" velocity="1"/>
    <dynamics damping="0.5" friction="0.2"/>
  </joint>

  <!-- RingProximal Gearbox -->
  <link name="Ring_ProximalGearbox_link">
    <visual>
      <origin xyz="0 -0.003 0" rpy="0 0 0"/>
      <geometry>
        <mesh filename="package://hands_one/meshes/Gearbox1.stl" scale="0.001 0.001 0.001"/>
      </geometry>
      <material name="green">
        <color rgba="0 1 0 1"/>
      </material>
    </visual>
    <collision>
      <origin xyz="0 -0.003 0" rpy="0 0 0"/>
      <geometry>
        <mesh filename="package://hands_one/meshes/Gearbox1.stl" scale="0.001 0.001 0.001"/>
      </geometry>
    </collision>
    <inertial>
      <mass value="0.1"/>
      <origin xyz="0 0 0" rpy="0 0 0"/>
      <inertia ixx="0.0001" ixy="0" ixz="0" iyy="0.0001" iyz="0" izz="0.0001"/>
    </inertial>
  </link>

  <!-- Joint connecting Ring Finger Gearbox to Ring Finger Mechanism -->
  <joint name="Ring_ProximalGearbox_joint" type="revolute">
    <parent link="RingMechanism_link"/>
    <child link="Ring_ProximalGearbox_link"/>
    <origin xyz="0 0.02375 -0.003" rpy="0 -1.57 -3.14159"/>
    <axis xyz="0 0 1"/>
    <limit lower="-0.3" upper="1.57" effort="1" velocity="1"/>
    <dynamics damping="0.5" friction="0.2"/>
  </joint>


  <!-- MiddleProximal Gearbox -->
  <link name="Middle_ProximalGearbox_link">
    <visual>
      <origin xyz="0 -0.003 0" rpy="0 0 0"/>
      <geometry>
        <mesh filename="package://hands_one/meshes/Gearbox1.stl" scale="0.001 0.001 0.001"/>
      </geometry>
      <material name="green">
        <color rgba="0 1 0 1"/>
      </material>
    </visual>
    <collision>
      <origin xyz="0 -0.003 0" rpy="0 0 0"/>
      <geometry>
        <mesh filename="package://hands_one/meshes/Gearbox1.stl" scale="0.001 0.001 0.001"/>
      </geometry>
    </collision>
    <inertial>
      <mass value="0.1"/>
      <origin xyz="0 0 0" rpy="0 0 0"/>
      <inertia ixx="0.0001" ixy="0" ixz="0" iyy="0.0001" iyz="0" izz="0.0001"/>
    </inertial>
  </link>

  <!-- Joint connecting Middle Finger Gearbox to Middle Finger Mechanism -->
  <joint name="Middle_ProximalGearbox_joint" type="revolute">
    <parent link="MiddleMechanism_link"/>
    <child link="Middle_ProximalGearbox_link"/>
    <origin xyz="0 0.02375 -0.003" rpy="0 -1.57 -3.14159"/>
    <axis xyz="0 0 1"/>
    <limit lower="-0.3" upper="1.57" effort="1" velocity="1"/>
    <dynamics damping="0.5" friction="0.2"/>
  </joint>

  <!-- IndexProximal Gearbox -->
  <link name="Index_ProximalGearbox_link">
    <visual>
      <origin xyz="0 -0.003 0" rpy="0 0 0"/>
      <geometry>
        <mesh filename="package://hands_one/meshes/Gearbox1.stl" scale="0.001 0.001 0.001"/>
      </geometry>
      <material name="green">
        <color rgba="0 1 0 1"/>
      </material>
    </visual>
    <collision>
      <origin xyz="0 -0.003 0" rpy="0 0 0"/>
      <geometry>
        <mesh filename="package://hands_one/meshes/Gearbox1.stl" scale="0.001 0.001 0.001"/>
      </geometry>
    </collision>
    <inertial>
      <mass value="0.1"/>
      <origin xyz="0 0 0" rpy="0 0 0"/>
      <inertia ixx="0.0001" ixy="0" ixz="0" iyy="0.0001" iyz="0" izz="0.0001"/>
    </inertial>
  </link>

  <!-- Joint connecting Index Finger Gearbox to Index Finger Mechanism -->
  <joint name="Index_ProximalGearbox_joint" type="revolute">
    <parent link="IndexMechanism_link"/>
    <child link="Index_ProximalGearbox_link"/>
    <origin xyz="0 0.02375 -0.003" rpy="0 -1.57 -3.14159"/>
    <axis xyz="0 0 1"/>
    <limit lower="-0.3" upper="1.57" effort="1" velocity="1"/>
    <dynamics damping="0.5" friction="0.2"/>
  </joint>

  <!-- ThumbProximal Gearbox -->
  <link name="Thumb_ProximalGearbox_link">
    <visual>
      <origin xyz="0 -0.003 0" rpy="0 0 0"/>
      <geometry>
        <mesh filename="package://hands_one/meshes/Gearbox1.stl" scale="0.001 0.001 0.001"/>
      </geometry>
      <material name="green">
        <color rgba="0 1 0 1"/>
      </material>
    </visual>
    <collision>
      <origin xyz="0 -0.003 0" rpy="0 0 0"/>
      <geometry>
        <mesh filename="package://hands_one/meshes/Gearbox1.stl" scale="0.001 0.001 0.001"/>
      </geometry>
    </collision>
    <inertial>
      <mass value="0.1"/>
      <origin xyz="0 0 0" rpy="0 0 0"/>
      <inertia ixx="0.0001" ixy="0" ixz="0" iyy="0.0001" iyz="0" izz="0.0001"/>
    </inertial>
  </link>

  <!-- Joint connecting Thumb Finger Gearbox to Thumb Finger Mechanism -->
  <joint name="Thumb_ProximalGearbox_joint" type="revolute">
    <parent link="ThumbMechanism_link"/>
    <child link="Thumb_ProximalGearbox_link"/>
    <origin xyz="0 0.02375 -0.003" rpy="0 -1.57 -3.14159"/>
    <axis xyz="0 0 1"/>
    <limit lower="-1.0" upper="1.57" effort="1" velocity="1"/>
    <dynamics damping="0.5" friction="0.2"/>
  </joint>

  <!-- Little Proximal Link -->
  <link name="Little_Proximal_link">
    <visual>
      <geometry>
        <mesh filename="package://hands_one/meshes/LittleProximalUpdated.stl" scale="0.001 0.001 0.001"/>
      </geometry>
      <material name="gray">
        <color rgba="0.5 0.5 0.5 0.5"/>
      </material>
    </visual>
    <collision>
      <geometry>
        <mesh filename="package://hands_one/meshes/LittleProximalUpdated.stl" scale="0.001 0.001 0.001"/>
      </geometry>
    </collision>
    <inertial>
      <mass value="0.1"/>
      <origin xyz="0 0 0" rpy="0 0 0"/>
      <inertia ixx="0.0001" ixy="0" ixz="0" iyy="0.0001" iyz="0" izz="0.0001"/>
    </inertial>
  </link>

  <!-- Joint connecting Little Finger Proximal Link to Little Finger Gearbox -->
  <joint name="Little_Proximal_joint" type="fixed">
    <parent link="Little_ProximalGearbox_link"/>
    <child link="Little_Proximal_link"/>
    <origin xyz="0 -0.0276 0" rpy="0 1.5708 0"/>
  </joint>

  <!-- Ring Proximal Link -->
  <link name="Ring_Proximal_link">
    <visual>
      <geometry>
        <mesh filename="package://hands_one/meshes/IndexProximalUpdated.stl" scale="0.001 0.001 0.001"/>
      </geometry>
      <material name="gray">
        <color rgba="0.5 0.5 0.5 1"/>
      </material>
    </visual>
    <collision>
      <geometry>
        <mesh filename="package://hands_one/meshes/IndexProximalUpdated.stl" scale="0.001 0.001 0.001"/>
      </geometry>
    </collision>
    <inertial>
      <mass value="0.1"/>
      <origin xyz="0 0 0" rpy="0 0 0"/>
      <inertia ixx="0.0001" ixy="0" ixz="0" iyy="0.0001" iyz="0" izz="0.0001"/>
    </inertial>
  </link>

  <!-- Joint connecting Ring Finger Proximal Link to Ring Finger Gearbox -->
  <joint name="Ring_Proximal_joint" type="fixed">
    <parent link="Ring_ProximalGearbox_link"/>
    <child link="Ring_Proximal_link"/>
    <origin xyz="0 -0.0296 0" rpy="0 1.5708 0"/>
  </joint>

  <!-- Middle Proximal Link -->
  <link name="Middle_Proximal_link">
    <visual>
      <geometry>
        <mesh filename="package://hands_one/meshes/IndexProximalUpdated.stl" scale="0.001 0.001 0.001"/>
      </geometry>
      <material name="gray">
        <color rgba="0.5 0.5 0.5 1"/>
      </material>
    </visual>
    <collision>
      <geometry>
        <mesh filename="package://hands_one/meshes/IndexProximalUpdated.stl" scale="0.001 0.001 0.001"/>
      </geometry>
    </collision>
    <inertial>
      <mass value="0.1"/>
      <origin xyz="0 0 0" rpy="0 0 0"/>
      <inertia ixx="0.0001" ixy="0" ixz="0" iyy="0.0001" iyz="0" izz="0.0001"/>
    </inertial>
  </link>

  <!-- Joint connecting Middle Finger Proximal Link to Middle Finger Gearbox -->
  <joint name="Middle_Proximal_joint" type="fixed">
    <parent link="Middle_ProximalGearbox_link"/>
    <child link="Middle_Proximal_link"/>
    <origin xyz="0 -0.0296 0" rpy="0 1.5708 0"/>
  </joint>

  <!-- Index Proximal Link -->
  <link name="Index_Proximal_link">
    <visual>
      <geometry>
        <mesh filename="package://hands_one/meshes/IndexProximalUpdated.stl" scale="0.001 0.001 0.001"/>
      </geometry>
      <material name="gray">
        <color rgba="0.5 0.5 0.5 1"/>
      </material>
    </visual>
    <collision>
      <geometry>
        <mesh filename="package://hands_one/meshes/IndexProximalUpdated.stl" scale="0.001 0.001 0.001"/>
      </geometry>
    </collision>
    <inertial>
      <mass value="0.1"/>
      <origin xyz="0 0 0" rpy="0 0 0"/>
      <inertia ixx="0.0001" ixy="0" ixz="0" iyy="0.0001" iyz="0" izz="0.0001"/>
    </inertial>
  </link>

  <!-- Joint connecting Index Finger Proximal Link to Index Finger Gearbox -->
  <joint name="Index_Proximal_joint" type="fixed">
    <parent link="Index_ProximalGearbox_link"/>
    <child link="Index_Proximal_link"/>
    <origin xyz="0 -0.0296 0" rpy="0 1.5708 0"/>
  </joint>

  <!-- Thumb Proximal Link -->
  <link name="Thumb_Proximal_link">
    <visual>
      <geometry>
        <mesh filename="package://hands_one/meshes/ThumbProximal.stl" scale="0.001 0.001 0.001"/>
      </geometry>
      <material name="gray">
        <color rgba="0.5 0.5 0.5 1"/>
      </material>
    </visual>
    <collision>
      <geometry>
        <mesh filename="package://hands_one/meshes/ThumbProximal.stl" scale="0.001 0.001 0.001"/>
      </geometry>
    </collision>
    <inertial>
      <mass value="0.1"/>
      <origin xyz="0 0 0" rpy="0 0 0"/>
      <inertia ixx="0.0001" ixy="0" ixz="0" iyy="0.0001" iyz="0" izz="0.0001"/>
    </inertial>
  </link>

  <!-- Joint connecting Thumb Finger Proximal Link to Thumb Finger Gearbox -->
  <joint name="Thumb_Proximal_joint" type="fixed">
    <parent link="Thumb_ProximalGearbox_link"/>
    <child link="Thumb_Proximal_link"/>
    <origin xyz="0 -0.0271 0" rpy="0 1.5708 0"/>
  </joint>

  <!-- Little Middle Gearbox -->
  <link name="Little_MiddleGearbox_link">
    <visual>
      <geometry>
        <mesh filename="package://hands_one/meshes/Gearbox1.stl" scale="0.001 0.001 0.001"/>
      </geometry>
      <material name="green">
        <color rgba="0 1 0 1"/>
      </material>
    </visual>
    <collision>
      <geometry>
        <mesh filename="package://hands_one/meshes/Gearbox1.stl" scale="0.001 0.001 0.001"/>
      </geometry>
    </collision>
    <inertial>
      <mass value="0.1"/>
      <origin xyz="0 0 0" rpy="0 0 0"/>
      <inertia ixx="0.0001" ixy="0" ixz="0" iyy="0.0001" iyz="0" izz="0.0001"/>
    </inertial>
  </link>

  <!-- Joint connecting Little Finger Proximal Link to Little Finger Gearbox -->
  <joint name="Little_MiddleGearbox_joint" type="fixed">
    <parent link="Little_Proximal_link"/>
    <child link="Little_MiddleGearbox_link"/>
    <origin xyz="0 -0.0246 0" rpy="3.14159 -1.5708 0"/>
  </joint>

  <!-- Ring Middle Gearbox -->
  <link name="Ring_MiddleGearbox_link">
    <visual>
      <geometry>
        <mesh filename="package://hands_one/meshes/Gearbox1.stl" scale="0.001 0.001 0.001"/>
      </geometry>
      <material name="green">
        <color rgba="0 1 0 1"/>
      </material>
    </visual>
    <collision>
      <geometry>
        <mesh filename="package://hands_one/meshes/Gearbox1.stl" scale="0.001 0.001 0.001"/>
      </geometry>
    </collision>
    <inertial>
      <mass value="0.1"/>
      <origin xyz="0 0 0" rpy="0 0 0"/>
      <inertia ixx="0.0001" ixy="0" ixz="0" iyy="0.0001" iyz="0" izz="0.0001"/>
    </inertial>
  </link>

  <!-- Joint connecting Ring Finger Proximal Link to Ring Finger Gearbox -->
  <joint name="Ring_MiddleGearbox_joint" type="fixed">
    <parent link="Ring_Proximal_link"/>
    <child link="Ring_MiddleGearbox_link"/>
    <origin xyz="0 -0.0266 0" rpy="3.14159 -1.5708 0"/>
  </joint>


  <!-- Middle Middle Gearbox -->
  <link name="Middle_MiddleGearbox_link">
    <visual>
      <geometry>
        <mesh filename="package://hands_one/meshes/Gearbox1.stl" scale="0.001 0.001 0.001"/>
      </geometry>
      <material name="green">
        <color rgba="0 1 0 1"/>
      </material>
    </visual>
    <collision>
      <geometry>
        <mesh filename="package://hands_one/meshes/Gearbox1.stl" scale="0.001 0.001 0.001"/>
      </geometry>
    </collision>
    <inertial>
      <mass value="0.1"/>
      <origin xyz="0 0 0" rpy="0 0 0"/>
      <inertia ixx="0.0001" ixy="0" ixz="0" iyy="0.0001" iyz="0" izz="0.0001"/>
    </inertial>
  </link>

  <!-- Joint connecting Middle Finger Proximal Link to Middle Finger Gearbox -->
  <joint name="Middle_MiddleGearbox_joint" type="fixed">
    <parent link="Middle_Proximal_link"/>
    <child link="Middle_MiddleGearbox_link"/>
    <origin xyz="0 -0.0266 0" rpy="3.14159 -1.5708 0"/>
  </joint>


  <!-- Index Middle Gearbox -->
  <link name="Index_MiddleGearbox_link">
    <visual>
      <geometry>
        <mesh filename="package://hands_one/meshes/Gearbox1.stl" scale="0.001 0.001 0.001"/>
      </geometry>
      <material name="green">
        <color rgba="0 1 0 1"/>
      </material>
    </visual>
    <collision>
      <geometry>
        <mesh filename="package://hands_one/meshes/Gearbox1.stl" scale="0.001 0.001 0.001"/>
      </geometry>
    </collision>
    <inertial>
      <mass value="0.1"/>
      <origin xyz="0 0 0" rpy="0 0 0"/>
      <inertia ixx="0.0001" ixy="0" ixz="0" iyy="0.0001" iyz="0" izz="0.0001"/>
    </inertial>
  </link>

  <!-- Joint connecting Index Finger Proximal Link to Index Finger Gearbox -->
  <joint name="Index_MiddleGearbox_joint" type="fixed">
    <parent link="Index_Proximal_link"/>
    <child link="Index_MiddleGearbox_link"/>
    <origin xyz="0 -0.0266 0" rpy="3.14159 -1.5708 0"/>
  </joint>

  <!-- Thumb Middle Gearbox -->
  <link name="Thumb_MiddleGearbox_link">
    <visual>
      <geometry>
        <mesh filename="package://hands_one/meshes/Gearbox1.stl" scale="0.001 0.001 0.001"/>
      </geometry>
      <material name="green">
        <color rgba="0 1 0 1"/>
      </material>
    </visual>
    <collision>
      <geometry>
        <mesh filename="package://hands_one/meshes/Gearbox1.stl" scale="0.001 0.001 0.001"/>
      </geometry>
    </collision>
    <inertial>
      <mass value="0.1"/>
      <origin xyz="0 0 0" rpy="0 0 0"/>
      <inertia ixx="0.0001" ixy="0" ixz="0" iyy="0.0001" iyz="0" izz="0.0001"/>
    </inertial>
  </link>

  <!-- Joint connecting Thumb Finger Proximal Link to Thumb Finger Gearbox -->
  <joint name="Thumb_MiddleGearbox_joint" type="fixed">
    <parent link="Thumb_Proximal_link"/>
    <child link="Thumb_MiddleGearbox_link"/>
    <origin xyz="0 -0.0241 0" rpy="3.14159 0 0"/>
  </joint>

  <!-- LittleMiddle Link -->
  <link name="Little_Middle_link">
    <visual>
      <origin xyz="0 0.0135 0" rpy="0 0 0"/>
      <geometry>
        <mesh filename="package://hands_one/meshes/IndexMiddleUpdated.stl" scale="0.001 0.001 0.001"/>
      </geometry>
      <material name="gray">
        <color rgba="0.5 0.5 0.5 1"/>
      </material>
    </visual>
    <collision>
      <origin xyz="0 0.0135 0" rpy="0 0 0"/>
      <geometry>
        <mesh filename="package://hands_one/meshes/IndexMiddleUpdated.stl" scale="0.001 0.001 0.001"/>
      </geometry>
    </collision>
    <inertial>
      <mass value="0.1"/>
      <origin xyz="0 0 0" rpy="0 0 0"/>
      <inertia ixx="0.0001" ixy="0" ixz="0" iyy="0.0001" iyz="0" izz="0.0001"/>
    </inertial>
  </link>

  <!-- Joint connecting Little Finger Middle Gearbox to Little Finger Middle Link -->
  <joint name="Little_Middle_joint" type="revolute">
    <parent link="Little_MiddleGearbox_link"/>
    <child link="Little_Middle_link"/>
    <origin xyz="0 0.003 0" rpy="0 1.57 0"/>
    <axis xyz="1 0 0"/>
    <limit lower="0" upper="1.57" effort="1" velocity="1"/>
    <dynamics damping="0.5" friction="0.2"/>
  </joint>

  <!-- RingMiddle Link -->
  <link name="Ring_Middle_link">
    <visual>
      <origin xyz="0 0.0135 0" rpy="0 0 0"/>
      <geometry>
        <mesh filename="package://hands_one/meshes/IndexMiddleUpdated.stl" scale="0.001 0.001 0.001"/>
      </geometry>
      <material name="gray">
        <color rgba="0.5 0.5 0.5 1"/>
      </material>
    </visual>
    <collision>
      <origin xyz="0 0.0135 0" rpy="0 0 0"/>
      <geometry>
        <mesh filename="package://hands_one/meshes/IndexMiddleUpdated.stl" scale="0.001 0.001 0.001"/>
      </geometry>
    </collision>
    <inertial>
      <mass value="0.1"/>
      <origin xyz="0 0 0" rpy="0 0 0"/>
      <inertia ixx="0.0001" ixy="0" ixz="0" iyy="0.0001" iyz="0" izz="0.0001"/>
    </inertial>
  </link>

  <!-- Joint connecting Ring Finger Middle Gearbox to Ring Finger Middle Link -->
  <joint name="Ring_Middle_joint" type="revolute">
    <parent link="Ring_MiddleGearbox_link"/>
    <child link="Ring_Middle_link"/>
    <origin xyz="0 0.003 0" rpy="0 1.57 0"/>
    <axis xyz="1 0 0"/>
    <limit lower="0" upper="1.57" effort="1" velocity="1"/>
    <dynamics damping="0.5" friction="0.2"/>
  </joint>

  <!-- MiddleMiddle Link -->
  <link name="Middle_Middle_link">
    <visual>
      <origin xyz="0 0.0135 0" rpy="0 0 0"/>
      <geometry>
        <mesh filename="package://hands_one/meshes/IndexMiddleUpdated.stl" scale="0.001 0.001 0.001"/>
      </geometry>
      <material name="gray">
        <color rgba="0.5 0.5 0.5 1"/>
      </material>
    </visual>
    <collision>
      <origin xyz="0 0.0135 0" rpy="0 0 0"/>
      <geometry>
        <mesh filename="package://hands_one/meshes/IndexMiddleUpdated.stl" scale="0.001 0.001 0.001"/>
      </geometry>
    </collision>
    <inertial>
      <mass value="0.1"/>
      <origin xyz="0 0 0" rpy="0 0 0"/>
      <inertia ixx="0.0001" ixy="0" ixz="0" iyy="0.0001" iyz="0" izz="0.0001"/>
    </inertial>
  </link>

  <!-- Joint connecting Middle Finger Middle Gearbox to Middle Finger Middle Link -->
  <joint name="Middle_Middle_joint" type="revolute">
    <parent link="Middle_MiddleGearbox_link"/>
    <child link="Middle_Middle_link"/>
    <origin xyz="0 0.003 0" rpy="0 1.57 0"/>
    <axis xyz="1 0 0"/>
    <limit lower="0" upper="1.57" effort="1" velocity="1"/>
    <dynamics damping="0.5" friction="0.2"/>
  </joint>

  <!-- IndexMiddle Link -->
  <link name="Index_Middle_link">
    <visual>
      <origin xyz="0 0.0135 0" rpy="0 0 0"/>
      <geometry>
        <mesh filename="package://hands_one/meshes/IndexMiddleUpdated.stl" scale="0.001 0.001 0.001"/>
      </geometry>
      <material name="gray">
        <color rgba="0.5 0.5 0.5 1"/>
      </material>
    </visual>
    <collision>
      <origin xyz="0 0.0135 0" rpy="0 0 0"/>
      <geometry>
        <mesh filename="package://hands_one/meshes/IndexMiddleUpdated.stl" scale="0.001 0.001 0.001"/>
      </geometry>
    </collision>
    <inertial>
      <mass value="0.1"/>
      <origin xyz="0 0 0" rpy="0 0 0"/>
      <inertia ixx="0.0001" ixy="0" ixz="0" iyy="0.0001" iyz="0" izz="0.0001"/>
    </inertial>
  </link>

  <!-- Joint connecting Index Finger Middle Gearbox to Index Finger Middle Link -->
  <joint name="Index_Middle_joint" type="revolute">
    <parent link="Index_MiddleGearbox_link"/>
    <child link="Index_Middle_link"/>
    <origin xyz="0 0.003 0" rpy="0 1.57 0"/>
    <axis xyz="1 0 0"/>
    <limit lower="0" upper="1.57" effort="1" velocity="1"/>
    <dynamics damping="0.5" friction="0.2"/>
  </joint>

  <link name="Thumb_Middle_link">
    <visual>
      <origin xyz="0 0.0135 0" rpy="0 0 0"/>
      <geometry>
        <mesh filename="package://hands_one/meshes/IndexMiddleUpdated.stl" scale="0.001 0.001 0.001"/>
      </geometry>
      <material name="gray">
        <color rgba="0.5 0.5 0.5 1"/>
      </material>
    </visual>
    <collision>
      <origin xyz="0 0.0135 0" rpy="0 0 0"/>
      <geometry>
        <mesh filename="package://hands_one/meshes/IndexMiddleUpdated.stl" scale="0.001 0.001 0.001"/>
      </geometry>
    </collision>
    <inertial>
      <mass value="0.1"/>
      <origin xyz="0 0 0" rpy="0 0 0"/>
      <inertia ixx="0.0001" ixy="0" ixz="0" iyy="0.0001" iyz="0" izz="0.0001"/>
    </inertial>
  </link>

  <!-- Joint connecting Thumb Finger Middle Gearbox to Thumb Finger Middle Link -->
  <joint name="Thumb_Middle_joint" type="revolute">
    <parent link="Thumb_MiddleGearbox_link"/>
    <child link="Thumb_Middle_link"/>
    <origin xyz="0 0.003 0" rpy="0 1.57 0"/>
    <axis xyz="1 0 0"/>
    <limit lower="0" upper="1.57" effort="1" velocity="1"/>
    <dynamics damping="0.5" friction="0.2"/>
  </joint>

  <!-- Little Distal Gearbox -->
  <link name="Little_DistalGearbox_link">
    <visual>
      <geometry>
        <mesh filename="package://hands_one/meshes/Gearbox1.stl" scale="0.001 0.001 0.001"/>
      </geometry>
      <material name="green">
        <color rgba="0 1 0 1"/>
      </material>
    </visual>
    <collision>
      <geometry>
        <mesh filename="package://hands_one/meshes/Gearbox1.stl" scale="0.001 0.001 0.001"/>
      </geometry>
    </collision>
    <inertial>
      <mass value="0.1"/>
      <origin xyz="0 0 0" rpy="0 0 0"/>
      <inertia ixx="0.0001" ixy="0" ixz="0" iyy="0.0001" iyz="0" izz="0.0001"/>
    </inertial>
  </link>

  <!-- Joint connecting Little Finger Proximal Link to Little Finger Gearbox -->
  <joint name="Little_DistalGearbox_joint" type="fixed">
    <parent link="Little_Middle_link"/>
    <child link="Little_DistalGearbox_link"/>
    <origin xyz="0 0.0376 0" rpy="0 1.5708 0"/>
  </joint>

  <!-- Ring Distal Gearbox -->
  <link name="Ring_DistalGearbox_link">
    <visual>
      <geometry>
        <mesh filename="package://hands_one/meshes/Gearbox1.stl" scale="0.001 0.001 0.001"/>
      </geometry>
      <material name="green">
        <color rgba="0 1 0 1"/>
      </material>
    </visual>
    <collision>
      <geometry>
        <mesh filename="package://hands_one/meshes/Gearbox1.stl" scale="0.001 0.001 0.001"/>
      </geometry>
    </collision>
    <inertial>
      <mass value="0.1"/>
      <origin xyz="0 0 0" rpy="0 0 0"/>
      <inertia ixx="0.0001" ixy="0" ixz="0" iyy="0.0001" iyz="0" izz="0.0001"/>
    </inertial>
  </link>

  <!-- Joint connecting Ring Finger Proximal Link to Little Ring Gearbox -->
  <joint name="Ring_DistalGearbox_joint" type="fixed">
    <parent link="Ring_Middle_link"/>
    <child link="Ring_DistalGearbox_link"/>
    <origin xyz="0 0.0376 0" rpy="0 1.5708 0"/>
  </joint>

  <!-- Middle Distal Gearbox -->
  <link name="Middle_DistalGearbox_link">
    <visual>
      <geometry>
        <mesh filename="package://hands_one/meshes/Gearbox1.stl" scale="0.001 0.001 0.001"/>
      </geometry>
      <material name="green">
        <color rgba="0 1 0 1"/>
      </material>
    </visual>
    <collision>
      <geometry>
        <mesh filename="package://hands_one/meshes/Gearbox1.stl" scale="0.001 0.001 0.001"/>
      </geometry>
    </collision>
    <inertial>
      <mass value="0.1"/>
      <origin xyz="0 0 0" rpy="0 0 0"/>
      <inertia ixx="0.0001" ixy="0" ixz="0" iyy="0.0001" iyz="0" izz="0.0001"/>
    </inertial>
  </link>

  <!-- Joint connecting Middle Finger Proximal Link to Middle Finger Gearbox -->
  <joint name="Middle_DistalGearbox_joint" type="fixed">
    <parent link="Middle_Middle_link"/>
    <child link="Middle_DistalGearbox_link"/>
    <origin xyz="0 0.0376 0" rpy="0 1.5708 0"/>
  </joint>

  <!-- Index Distal Gearbox -->
  <link name="Index_DistalGearbox_link">
    <visual>
      <geometry>
        <mesh filename="package://hands_one/meshes/Gearbox1.stl" scale="0.001 0.001 0.001"/>
      </geometry>
      <material name="green">
        <color rgba="0 1 0 1"/>
      </material>
    </visual>
    <collision>
      <geometry>
        <mesh filename="package://hands_one/meshes/Gearbox1.stl" scale="0.001 0.001 0.001"/>
      </geometry>
    </collision>
    <inertial>
      <mass value="0.1"/>
      <origin xyz="0 0 0" rpy="0 0 0"/>
      <inertia ixx="0.0001" ixy="0" ixz="0" iyy="0.0001" iyz="0" izz="0.0001"/>
    </inertial>
  </link>

  <!-- Joint connecting Index Finger Proximal Link to Index Finger Gearbox -->
  <joint name="Index_DistalGearbox_joint" type="fixed">
    <parent link="Index_Middle_link"/>
    <child link="Index_DistalGearbox_link"/>
    <origin xyz="0 0.0376 0" rpy="0 1.5708 0"/>
  </joint>

  <!-- Thumb Distal Gearbox -->
  <link name="Thumb_DistalGearbox_link">
    <visual>
      <geometry>
        <mesh filename="package://hands_one/meshes/Gearbox1.stl" scale="0.001 0.001 0.001"/>
      </geometry>
      <material name="green">
        <color rgba="0 1 0 1"/>
      </material>
    </visual>
    <collision>
      <geometry>
        <mesh filename="package://hands_one/meshes/Gearbox1.stl" scale="0.001 0.001 0.001"/>
      </geometry>
    </collision>
    <inertial>
      <mass value="0.1"/>
      <origin xyz="0 0 0" rpy="0 0 0"/>
      <inertia ixx="0.0001" ixy="0" ixz="0" iyy="0.0001" iyz="0" izz="0.0001"/>
    </inertial>
  </link>

  <!-- Joint connecting Thumb Finger Proximal Link to Thumb Finger Gearbox -->
  <joint name="Thumb_DistalGearbox_joint" type="fixed">
    <parent link="Thumb_Middle_link"/>
    <child link="Thumb_DistalGearbox_link"/>
    <origin xyz="0 0.0376 0" rpy="0 1.5708 0"/>
  </joint>

  <!-- LittleDistal Link -->
  <link name="Little_Distal_link">
    <visual>
      <origin xyz="0 0.01095 0" rpy="0 0 0"/>
      <geometry>
        <mesh filename="package://hands_one/meshes/IndexDistalUpdated.stl" scale="0.001 0.001 0.001"/>
      </geometry>
      <material name="gray">
        <color rgba="0.5 0.5 0.5 1"/>
      </material>
    </visual>
    <collision>
      <origin xyz="0 0.01095 0" rpy="0 0 0"/>
      <geometry>
        <mesh filename="package://hands_one/meshes/IndexDistalUpdated.stl" scale="0.001 0.001 0.001"/>
      </geometry>
    </collision>
    <inertial>
      <mass value="0.1"/>
      <origin xyz="0 0 0" rpy="0 0 0"/>
      <inertia ixx="0.0001" ixy="0" ixz="0" iyy="0.0001" iyz="0" izz="0.0001"/>
    </inertial>
  </link>

  <!-- Joint connecting Little Finger Distal Gearbox to Little Finger Distal Link -->
  <joint name="Little_Distal_joint" type="revolute">
    <parent link="Little_DistalGearbox_link"/>
    <child link="Little_Distal_link"/>
    <origin xyz="0 0.00295 0" rpy="0 -1.57 0"/>
    <axis xyz="1 0 0"/>
    <limit lower="0" upper="1.57" effort="1" velocity="1"/>
    <dynamics damping="0.5" friction="0.2"/>
  </joint>

  <!-- RingDistal Link -->
  <link name="Ring_Distal_link">
    <visual>
      <origin xyz="0 0.01095 0" rpy="0 0 0"/>
      <geometry>
        <mesh filename="package://hands_one/meshes/IndexDistalUpdated.stl" scale="0.001 0.001 0.001"/>
      </geometry>
      <material name="gray">
        <color rgba="0.5 0.5 0.5 1"/>
      </material>
    </visual>
    <collision>
      <origin xyz="0 0.01095 0" rpy="0 0 0"/>
      <geometry>
        <mesh filename="package://hands_one/meshes/IndexDistalUpdated.stl" scale="0.001 0.001 0.001"/>
      </geometry>
    </collision>
    <inertial>
      <mass value="0.1"/>
      <origin xyz="0 0 0" rpy="0 0 0"/>
      <inertia ixx="0.0001" ixy="0" ixz="0" iyy="0.0001" iyz="0" izz="0.0001"/>
    </inertial>
  </link>

  <!-- Joint connecting Ring Finger Distal Gearbox to Ring Finger Distal Link -->
  <joint name="Ring_Distal_joint" type="revolute">
    <parent link="Ring_DistalGearbox_link"/>
    <child link="Ring_Distal_link"/>
    <origin xyz="0 0.00295 0" rpy="0 -1.57 0"/>
    <axis xyz="1 0 0"/>
    <limit lower="0" upper="1.57" effort="1" velocity="1"/>
    <dynamics damping="0.5" friction="0.2"/>
  </joint>

  <!-- MiddleDistal Link -->
  <link name="Middle_Distal_link">
    <visual>
      <origin xyz="0 0.01095 0" rpy="0 0 0"/>
      <geometry>
        <mesh filename="package://hands_one/meshes/IndexDistalUpdated.stl" scale="0.001 0.001 0.001"/>
      </geometry>
      <material name="gray">
        <color rgba="0.5 0.5 0.5 1"/>
      </material>
    </visual>
    <collision>
      <origin xyz="0 0.01095 0" rpy="0 0 0"/>
      <geometry>
        <mesh filename="package://hands_one/meshes/IndexDistalUpdated.stl" scale="0.001 0.001 0.001"/>
      </geometry>
    </collision>
    <inertial>
      <mass value="0.1"/>
      <origin xyz="0 0 0" rpy="0 0 0"/>
      <inertia ixx="0.0001" ixy="0" ixz="0" iyy="0.0001" iyz="0" izz="0.0001"/>
    </inertial>
  </link>

  <!-- Joint connecting Middle Finger Distal Gearbox to Middle Finger Distal Link -->
  <joint name="Middle_Distal_joint" type="revolute">
    <parent link="Middle_DistalGearbox_link"/>
    <child link="Middle_Distal_link"/>
    <origin xyz="0 0.00295 0" rpy="0 -1.57 0"/>
    <axis xyz="1 0 0"/>
    <limit lower="0" upper="1.57" effort="1" velocity="1"/>
    <dynamics damping="0.5" friction="0.2"/>
  </joint>

  <!-- IndexDistal Link -->
  <link name="Index_Distal_link">
    <visual>
      <origin xyz="0 0.01095 0" rpy="0 0 0"/>
      <geometry>
        <mesh filename="package://hands_one/meshes/IndexDistalUpdated.stl" scale="0.001 0.001 0.001"/>
      </geometry>
      <material name="gray">
        <color rgba="0.5 0.5 0.5 1"/>
      </material>
    </visual>
    <collision>
      <origin xyz="0 0.01095 0" rpy="0 0 0"/>
      <geometry>
        <mesh filename="package://hands_one/meshes/IndexDistalUpdated.stl" scale="0.001 0.001 0.001"/>
      </geometry>
    </collision>
    <inertial>
      <mass value="0.1"/>
      <origin xyz="0 0 0" rpy="0 0 0"/>
      <inertia ixx="0.0001" ixy="0" ixz="0" iyy="0.0001" iyz="0" izz="0.0001"/>
    </inertial>
  </link>

  <!-- Joint connecting Index Finger Distal Gearbox to Index Finger Distal Link -->
  <joint name="Index_Distal_joint" type="revolute">
    <parent link="Index_DistalGearbox_link"/>
    <child link="Index_Distal_link"/>
    <origin xyz="0 0.00295 0" rpy="0 -1.57 0"/>
    <axis xyz="1 0 0"/>
    <limit lower="0" upper="1.57" effort="1" velocity="1"/>
    <dynamics damping="0.5" friction="0.2"/>
  </joint>

  <!-- ThumbDistal Link -->
  <link name="Thumb_Distal_link">
    <visual>
      <origin xyz="0 0.01095 0" rpy="0 0 0"/>
      <geometry>
        <mesh filename="package://hands_one/meshes/IndexDistalUpdated.stl" scale="0.001 0.001 0.001"/>
      </geometry>
      <material name="gray">
        <color rgba="0.5 0.5 0.5 1"/>
      </material>
    </visual>
    <collision>
      <origin xyz="0 0.01095 0" rpy="0 0 0"/>
      <geometry>
        <mesh filename="package://hands_one/meshes/IndexDistalUpdated.stl" scale="0.001 0.001 0.001"/>
      </geometry>
    </collision>
    <inertial>
      <mass value="0.1"/>
      <origin xyz="0 0 0" rpy="0 0 0"/>
      <inertia ixx="0.0001" ixy="0" ixz="0" iyy="0.0001" iyz="0" izz="0.0001"/>
    </inertial>
  </link>

  <!-- Joint connecting Thumb Finger Distal Gearbox to Thumb Finger Distal Link -->
  <joint name="Thumb_Distal_joint" type="revolute">
    <parent link="Thumb_DistalGearbox_link"/>
    <child link="Thumb_Distal_link"/>
    <origin xyz="0 0.00295 0" rpy="0 -1.57 0"/>
    <axis xyz="1 0 0"/>
    <limit lower="0" upper="1.57" effort="1" velocity="1"/>
    <dynamics damping="0.5" friction="0.2"/>
  </joint>

  <ros2_control name="GazeboSystem" type="system">

    <hardware>
      <plugin>gazebo_ros2_control/GazeboSystem</plugin>
    </hardware>

    <!-- THUMB (indices 0-2) -->
    <joint name="Thumb_ProximalGearbox_joint">
      <command_interface name="position"/>
      <state_interface name="position"/>
      <state_interface name="velocity"/>
    </joint>

    <joint name="Thumb_Middle_joint">
      <command_interface name="position"/>
      <state_interface name="position"/>
      <state_interface name="velocity"/>
    </joint>

    <joint name="Thumb_Distal_joint">
      <command_interface name="position"/>
      <state_interface name="position"/>
      <state_interface name="velocity"/>
    </joint>

    <!-- INDEX (indices 3-5) -->
    <joint name="Index_ProximalGearbox_joint">
      <command_interface name="position"/>
      <state_interface name="position"/>
      <state_interface name="velocity"/>
    </joint>

    <joint name="Index_Middle_joint">
      <command_interface name="position"/>
      <state_interface name="position"/>
      <state_interface name="velocity"/>
    </joint>

    <joint name="Index_Distal_joint">
      <command_interface name="position"/>
      <state_interface name="position"/>
      <state_interface name="velocity"/>
    </joint>

    <!-- MIDDLE (indices 6-8) -->
    <joint name="Middle_ProximalGearbox_joint">
      <command_interface name="position"/>
      <state_interface name="position"/>
      <state_interface name="velocity"/>
    </joint>

    <joint name="Middle_Middle_joint">
      <command_interface name="position"/>
      <state_interface name="position"/>
      <state_interface name="velocity"/>
    </joint>

    <joint name="Middle_Distal_joint">
      <command_interface name="position"/>
      <state_interface name="position"/>
      <state_interface name="velocity"/>
    </joint>

    <!-- RING (indices 9-11) -->
    <joint name="Ring_ProximalGearbox_joint">
      <command_interface name="position"/>
      <state_interface name="position"/>
      <state_interface name="velocity"/>
    </joint>

    <joint name="Ring_Middle_joint">
      <command_interface name="position"/>
      <state_interface name="position"/>
      <state_interface name="velocity"/>
    </joint>

    <joint name="Ring_Distal_joint">
      <command_interface name="position"/>
      <state_interface name="position"/>
      <state_interface name="velocity"/>
    </joint>

    <!-- LITTLE (indices 12-14) -->
    <joint name="Little_ProximalGearbox_joint">
      <command_interface name="position"/>
      <state_interface name="position"/>
      <state_interface name="velocity"/>
    </joint>

    <joint name="Little_Middle_joint">
      <command_interface name="position"/>
      <state_interface name="position"/>
      <state_interface name="velocity"/>
    </joint>

    <joint name="Little_Distal_joint">
      <command_interface name="position"/>
      <state_interface name="position"/>
      <state_interface name="velocity"/>
    </joint>

    <!-- MECHANISMS (indices 15-19) -->
    <joint name="ThumbMechanism_joint">
      <command_interface name="position"/>
      <state_interface name="position"/>
      <state_interface name="velocity"/>
    </joint>

    <joint name="IndexMechanism_joint">
      <command_interface name="position"/>
      <state_interface name="position"/>
      <state_interface name="velocity"/>
    </joint>

    <joint name="MiddleMechanism_joint">
      <command_interface name="position"/>
      <state_interface name="position"/>
      <state_interface name="velocity"/>
    </joint>

    <joint name="RingMechanism_joint">
      <command_interface name="position"/>
      <state_interface name="position"/>
      <state_interface name="velocity"/>
    </joint>

    <joint name="LittleMechanism_joint">
      <command_interface name="position"/>
      <state_interface name="position"/>
      <state_interface name="velocity"/>
    </joint>

  </ros2_control>
  
  
  <gazebo>
    <plugin name="gazebo_ros2_control" filename="libgazebo_ros2_control.so">
      <parameters>/home/robot/roboken/install/hands_one/share/hands_one/config/controllers.yaml</parameters>
    </plugin>
  </gazebo>

  <gazebo>
    <disable_collisions link1="Thumb_ProximalGearbox_link" link2="PalmFrontCover"/>
  </gazebo>

  <gazebo>
    <disable_collisions link1="ThumbMechanism_link" link2="PalmFrontCover"/>
  </gazebo>

</robot>